<robot xmlns:xacro="http://www.ros.org/wiki/xacro">
    <xacro:macro name="thruster" params="number *origin">
        <link name="thruster_${number}">
            <visual>
                <geometry>
                    <cylinder radius="0.05" length="0.1"/> 
                </geometry>
                <material name="blue"/>
            </visual>
            <collision>
                <geometry>
                    <cylinder radius="0.05" length="0.1"/>
                </geometry>
            </collision>
            <inertial>
                <mass value="0.01"/>
                <origin xyz="0 0 0" rpy="0 0 0"/>
                <inertia ixx="0.00833" ixy="0" ixz="0" iyy="0.00833" iyz="0" izz="0.00833"/>
            </inertial>
        </link>

        <joint name="thruster_${number}_joint" type="continuous">
            <parent link="base_link"/>
            <child link="thruster_${number}"/>
            <xacro:insert_block name="origin"/>
            <axis xyz="0 0 1"/>
        </joint>

        <gazebo>  
            <plugin filename="gz-sim-spacecraft-thruster-model-system" name="gz::sim::systems::SpacecraftThrusterModel">
                <link_name>thruster_${number}</link_name>
                <actuator_number>${number}</actuator_number>
                <duty_cycle_frequency>10</duty_cycle_frequency>
                <max_thrust>1.4</max_thrust>
                <topic>base</topic>
                <sub_topic>command/duty_cycle</sub_topic>
            </plugin>
        </gazebo>

    </xacro:macro>
</robot>