<?xml version="1.0" ?>
<sdf version="1.8">
  <model name="box_with_reaction_wheel">
    <static>false</static>
    <link name="box_link">
      <pose>0 0 0.15 0 0 0</pose>
      <inertial>
        <mass>1.0</mass>
        <inertia>
          <ixx>0.01</ixx>
          <iyy>0.01</iyy>
          <izz>0.01</izz>
          <ixy>0</ixy>
          <ixz>0</ixz>
          <iyz>0</iyz>
        </inertia>
      </inertial>
      <collision name="collision">
        <geometry>
          <box>
            <size>0.2 0.2 0.3</size>
          </box>
        </geometry>
         <surface>
          <contact>
            <ode>
              <kp>100000</kp>
              <kd>100000</kd>
            </ode>
          </contact>
          <friction>
            <ode>
              <mu>0</mu>
              <mu2>0</mu2>
              <fdir1>0 0 1</fdir1>
            </ode>
          </friction>
        </surface>
      </collision>
      <visual name="visual">
        <geometry>
          <box>
            <size>0.2 0.2 0.3</size>
          </box>
        </geometry>
        <material>
          <ambient>0.8 0.8 0.8 1</ambient>
          <diffuse>1 0 0 1</diffuse>
          <specular>0.8 0.8 0.8 1</specular>
          <emissive>0 0 0 1</emissive>
        </material>
      </visual>
    </link>

    <link name="reaction_wheel_link">
      <pose relative_to='reaction_wheel_joint'>0 0 0 0 0 0</pose>
      <inertial>
        <mass>0.1</mass>
        <inertia>
          <ixx>0.0001</ixx>
          <iyy>0.0001</iyy>
          <izz>0.0002</izz>
          <ixy>0</ixy>
          <ixz>0</ixz>
          <iyz>0</iyz>
        </inertia>
      </inertial>
      <collision name="collision">
        <geometry>
          <cylinder>
            <radius>0.05</radius>
            <length>0.02</length>
          </cylinder>
        </geometry>
      </collision>
      <visual name="visual">
        <geometry>
          <cylinder>
            <radius>0.05</radius>
            <length>0.02</length>
          </cylinder>
        </geometry>
        <material>
          <ambient>0.2 0.2 0.2 1</ambient>
          <diffuse>1 1 0 1</diffuse>
          <specular>0.1 0.1 0.1 1</specular>
          <emissive>0 0 0 1</emissive>
        </material>
      </visual>
    </link>

    <joint name="reaction_wheel_joint" type="revolute">
      <parent>box_link</parent>
      <child>reaction_wheel_link</child>
      <pose relative_to='box_link'>0 0 0.2 0 0 0</pose>
      <axis>
        <xyz>0 0 1</xyz>
        <limit>
          <lower>-1e16</lower>
          <upper>1e16</upper>
          <effort>100</effort>
          <velocity>10</velocity>
        </limit>
        <dynamics>
          <damping>0.01</damping>
          <friction>0.001</friction>
        </dynamics>
      </axis>
    </joint>

    <plugin filename="gz-sim-joint-controller-system" name="gz::sim::systems::JointController">
      <joint_name>reaction_wheel_joint</joint_name>
      <topic>rxn_vel</topic>
      <initial_velocity>10.0</initial_velocity>
    </plugin>
  </model>
</sdf>